Workbook

Sheet CI
F4: COMMERCIAL INVOICE
B5: Consignee : | I5: Invoice No. | M5: Date
B6: J. CARTER SPORTING CLUB LIMITED 1 CENTRAL STREET, MANCHESTER, UNITED KINGDOM,, M2 5WR | I6: 0654/INV/2025 | M6: 45810
I7: Term of Payment | K7: : | L7: LC - 180 DAYS AFTER BILL OF LADING DATE OR AIRWAY BILL DATE
I9: Bank Ref./LC No. | K9: : | L9: IMP750070263
I11: Date of Issue | K11: : | L11: 45225
B12: Notify Party : | I12: Issued by | K12: :
B13: J. CARTER SPORTING CLUB LIMITED 1 CENTRAL STREET, MANCHESTER, UNITED KINGDOM,, M2 5WR | I13: LOYDGB2LDIO
I17: HBL / HAWB No. | K17: :
I18: Shipped on Board Date | K18: :
B19: Port of Loading : | F19: Port of Discharge : | I19: PO NO
B20: SOEKARNO HATTA, JAKARTA AIRPORT, INDONESIA | F20: AMSTERDAM, NL | I20: EPO12508755, EPO12508757, WPO12508771, WPO12508772
F21: Port of Delivery :
F22: AMSTERDAM, NL
B23: Ship Mode | D23: : | E23: AIR
B24: BOOKING NO | D24: : | E24: CA25000660
B28: Description of Goods | L28: Quantity | M28: Unit Price | N28: Amount
L29: PIECES | M29: USD | N29: FCA
B32: 116 CARTONS = 3,711 PIECES OF APPAREL GOODS
B33: CONSIST OF :
B35: 52 CARTONS = 1,758 PIECES OF APPAREL GOODS
B36: PO NO. : EPO12508755
B37: ORDER LINE | C37: STYLE NO | E37: DESCRIPTION | J37: HS CODE
B38: 001 | C38: TI12081-010 | E38: FC UTRECHT PERFORMANCE KNIT SUIT | J38: 61109000 | L38: 100 | M38: 15.28 | N38: =M38*L38 -> 1528
B39: 003 | C39: TJ12049-010 | E39: FC UTRECHT PERFORMANCE KNIT SHORT- PKTS | J39: 61034900 | L39: 100 | M39: 6.74 | N39: =L39*M39 -> 674
B40: 004 | C40: TJ12050-010 | E40: FC UTRECHT PERFORMANCE MIDLAYER TOP | J40: 61109000 | L40: 150 | M40: 11.08 | N40: =L40*M40 -> 1662
B41: 005 | C41: TJ12052-010 | E41: FC UTRECHT PERFORMANCE KNIT PANT- PKTS | J41: 61034900 | L41: 100 | M41: 11.92 | N41: =L41*M41 -> 1192
B42: 007 | C42: TM12049-010 | E42: FC UTRECHT PERFORMANCE KNIT SHORT- PKTS | J42: 61034900 | L42: 206 | M42: 7.52 | N42: =L42*M42 -> 1549.12
B43: 008 | C43: TM12050-010 | E43: FC UTRECHT PERFORMANCE MIDLAYER TOP | J43: 61109000 | L43: 300 | M43: 12.33 | N43: =L43*M43 -> 3699
B44: 009 | C44: TM12052-010 | E44: FC UTRECHT PERFORMANCE KNIT PANT- PKTS | J44: 61034900 | L44: 202 | M44: 13.27 | N44: =L44*M44 -> 2680.54
B45: 002 | C45: TJ12046-072 | E45: FC UTRECHT PERFORMANCE SHORT SLEEVE TEE | J45: 61099020 | L45: 200 | M45: 4.87 | N45: =L45*M45 -> 974
B46: 006 | C46: TM12046-072 | E46: FC UTRECHT PERFORMANCE SHORT SLEEVE TEE | J46: 61099020 | L46: 400 | M46: 5.44 | N46: =L46*M46 -> 2176
B48: SUB TOTAL | L48: =SUM(L38:L46) -> 1758 | N48: =SUM(N38:N46) -> 16134.66
B50: 35 CARTONS = 1200 PIECES OF APPAREL GOODS
B51: PO NO. : WPO12508771
B52: ORDER LINE | C52: STYLE NO | E52: DESCRIPTION | J52: HS CODE
B53: 001 | C53: TI12081-010 | E53: FC UTRECHT PERFORMANCE KNIT SUIT | J53: 61109000 | L53: 25 | M53: 15.28 | N53: =M53*L53 -> 382
B54: 002 | C54: TJ12046-072 | E54: FC UTRECHT PERFORMANCE SHORT SLEEVE TEE | J54: 61099020 | L54: 171 | M54: 4.87 | N54: =L54*M54 -> 832.77
B55: 003 | C55: TJ12049-010 | E55: FC UTRECHT PERFORMANCE KNIT SHORT- PKTS | J55: 61034900 | L55: 141 | M55: 6.74 | N55: =L55*M55 -> 950.34
B56: 004 | C56: TJ12050-010 | E56: FC UTRECHT PERFORMANCE MIDLAYER TOP | J56: 61109000 | L56: 126 | M56: 11.08 | N56: =L56*M56 -> 1396.08
...

Sheet PL FC Utrecht
C4: PACKING LIST
A6: Consignee : | C6: Notify Party : | I6: DATE | O6: : | R6: 45810
A7: J. CARTER SPORTING CLUB LIMITED 1 CENTRAL STREET, MANCHESTER, M2 5WR UNITED KINGDOM, | C7: J. CARTER SPORTING CLUB LIMITED 1 CENTRAL STREET, MANCHESTER, M2 5WR UNITED KINGDOM, | I7: INVOICE | O7: : | R7: 0654/INV/2025
I8: L/C NO. | O8: : | R8: IMP750070263
I9: DATE OF ISSUE | O9: : | R9: 45956
I10: HBL / HAWB NO. | O10: :
I11: SHIPPED ON BOARD DATE | O11: :
I12: PORT OF DISCHARGE | O12: : | R12: AMSTERDAM, NL
I13: COUNTRY OF ORIGIN | O13: : | R13: INDONESIA
I14: PORT OF DELIVERY | O14: : | R14: AMSTERDAM, NL
I15: CONTAINER / SIZE / SEAL NO. | O15: :
A17: NAME OF VESSEL / FLIGHT | C17: TBA
A18: PORT OF SHIPMENT | C18: SOEKARNO HATTA, JAKARTA AIRPORT, INDONESIA
A19: MAIN MARK | I19: DESCRIPTION OF GOODS
I20: INTERNAL ID-51808115-E-COMMERCE
I26: PO NO. EPO12508755
A27: STYLE | B27: STYLE DESCRIPTION | C27: OP NO | D27: ORDER | E27: SIZE | O27: C/NO | R27: TOT | S27: TOT | T27: GW | U27: NW | V27: GW | W27: NW | X27: CARTON | Y27: CBM | Z27: POLYBAG
D28: LINE | E28: 2-3Y | F28: 3-4Y | G28: 4-5Y | H28: 5-6Y | I28: 6-7Y | R28: CTN | S28: PCS | T28: CARTON | U28: CARTON | V28: ( Kg ) | W28: ( Kg ) | X28: MEAS | Z28: WEIGHT
A29: TI12081-010 | B29: FC UTRECHT PERFORMANCE KNIT SUIT | C29: 25-02175B-1 | D29: 001 | H29: 24 | O29: 1 | Q29: =O29+R29-1 -> 1 | R29: 1 | S29: =SUM(E29:N29)*R29 -> 24 | T29: =IF(X29="595X289X390",1.46,IF(X29="597X292X191",0.96,IF(X29="560X600X390",2.04,IF(X29="560X400X390",1.84))))+U29 -> 11.54 | U29: =+((E29*0.35)+(F29*0.37)+(G29*0.39)+(H29*0.42)+(I29*0.44)+(J29*0.46)+(K29*0.456)+(L29*0.468)+(M29*0.478)) -> 10.08 | V29: =T29*R29 -> 11.54 | W29: =U29*R29 -> 10.08 | X29: 595X289X390 | Y29: =IF(X29="595X289X390",0.071,IF(X29="597X292X191",0.034,IF(X29="560X600X390",0.132,IF(X29="560X400X390",0.088))))*R29 -> 0.071 | Z29: 0
E30: 3 | G30: 22 | O30: =Q29+1 -> 2 | Q30: =O30+R30-1 -> 2 | R30: 1 | S30: =SUM(E30:N30)*R30 -> 25 | T30: =IF(X30="595X289X390",1.46,IF(X30="597X292X191",0.96,IF(X30="560X600X390",2.04,IF(X30="560X400X390",1.84))))+U30 -> 11.09 | U30: =+((E30*0.35)+(F30*0.37)+(G30*0.39)+(H30*0.42)+(I30*0.44)+(J30*0.46)+(K30*0.456)+(L30*0.468)+(M30*0.478)) -> 9.63 | V30: =T30*R30 -> 11.09 | W30: =U30*R30 -> 9.63 | X30: 595X289X390 | Y30: =IF(X30="595X289X390",0.071,IF(X30="597X292X191",0.034,IF(X30="560X600X390",0.132,IF(X30="560X400X390",0.088))))*R30 -> 0.071 | Z30: 0
F31: 21 | I31: 4 | O31: =Q30+1 -> 3 | Q31: =O31+R31-1 -> 3 | R31: 1 | S31: =SUM(E31:N31)*R31 -> 25 | T31: =IF(X31="595X289X390",1.46,IF(X31="597X292X191",0.96,IF(X31="560X600X390",2.04,IF(X31="560X400X390",1.84))))+U31 -> 10.99 | U31: =+((E31*0.35)+(F31*0.37)+(G31*0.39)+(H31*0.42)+(I31*0.44)+(J31*0.46)+(K31*0.456)+(L31*0.468)+(M31*0.478)) -> 9.53 | V31: =T31*R31 -> 10.99 | W31: =U31*R31 -> 9.53 | X31: 595X289X390 | Y31: =IF(X31="595X289X390",0.071,IF(X31="597X292X191",0.034,IF(X31="560X600X390",0.132,IF(X31="560X400X390",0.088))))*R31 -> 0.071 | Z31: 0
E32: 12 | I32: 14 | O32: =Q31+1 -> 4 | Q32: =O32+R32-1 -> 4 | R32: 1 | S32: =SUM(E32:N32)*R32 -> 26 | T32: =IF(X32="595X289X390",1.46,IF(X32="597X292X191",0.96,IF(X32="560X600X390",2.04,IF(X32="560X400X390",1.84))))+U32 -> 11.82 | U32: =+((E32*0.35)+(F32*0.37)+(G32*0.39)+(H32*0.42)+(I32*0.44)+(J32*0.46)+(K32*0.456)+(L32*0.468)+(M32*0.478)) -> 10.36 | V32: =T32*R32 -> 11.82 | W32: =U32*R32 -> 10.36 | X32: 595X289X390 | Y32: =IF(X32="595X289X390",0.071,IF(X32="597X292X191",0.034,IF(X32="560X600X390",0.132,IF(X32="560X400X390",0.088))))*R32 -> 0.071 | Z32: 0
C33: SUB TOTAL | R33: =SUM(R29:R32) -> 4 | S33: =SUM(S29:S32) -> 100 | T33: =SUM(T29:T32) -> 45.44 | U33: =SUM(U29:U32) -> 39.6 | V33: =SUM(V29:V32) -> 45.44 | W33: =SUM(W29:W32) -> 39.6 | Y33: =SUM(Y29:Y32) -> 0.284 | Z33: =SUM(Z29:Z32) -> 0
C34: TOTAL SHIPPED | E34: 15 | F34: 21 | G34: 22 | H34: 24 | I34: 18 | O34: 100
C35: TOTAL ORDERED | E35: 15 | F35: 21 | G35: 22 | H35: 24 | I35: 18 | O35: 100
C36: SHORTAGE/OVER
C37: PERCENTAGE
A39: STYLE | B39: STYLE DESCRIPTION | C39: OP NO | D39: ORDER | E39: SIZE | O39: C/NO | R39: TOT | S39: TOT | T39: GW | U39: NW | V39: GW | W39: NW | X39: CARTON | Y39: CBM | Z39: POLYBAG
D40: LINE | E40: JXS | F40: JS | G40: JM | H40: JL | I40: JXL | R40: CTN | S40: PCS | T40: CARTON | U40: CARTON | V40: ( Kg ) | W40: ( Kg ) | X40: MEAS | Z40: WEIGHT
A41: TJ12049-010 | B41: FC UTRECHT PERFORMANCE KNIT SHORT- PKTS | C41: 25-02168C-1 | D41: 003 | E41: 10 | F41: 16 | G41: 24 | H41: 26 | I41: 24 | O41: =Q32+1 -> 5 | Q41: =O41+R41-1 -> 5 | R41: 1 | S41: =SUM(E41:N41)*R41 -> 100 | T41: 3.58 | U41: 2.6 | V41: 3.58 | W41: 2.6 | X41: 595X289X390 | Y41: =IF(X41="595X289X390",0.071,IF(X41="597X292X191",0.034,IF(X41="560X600X390",0.132,IF(X41="560X400X390",0.088))))*R41 -> 0.071 | Z41: 0
C43: SUB TOTAL | R43: =SUM(R41) -> 1 | S43: =SUM(S41) -> 100 | T43: 35.66 | U43: 30.76 | V43: 35.66 | W43: 30.76 | Y43: =SUM(Y41) -> 0.071 | Z43: 0
C44: TOTAL SHIPPED | E44: 10 | F44: 16 | G44: 24 | H44: 26 | I44: 24 | O44: =SUM(E44:N44) -> 100
C45: TOTAL ORDERED | E45: 10 | F45: 16 | G45: 24 | H45: 26 | I45: 24 | O45: =SUM(E45:N45) -> 100
C46: SHORTAGE/OVER
C47: PERCENTAGE
A49: STYLE | B49: STYLE DESCRIPTION | C49: OP NO | D49: ORDER | E49: SIZE | O49: C/NO | R49: TOT | S49: TOT | T49: GW | U49: NW | V49: GW | W49: NW | X49: CARTON | Y49: CBM | Z49: POLYBAG
D50: LINE | E50: JXS | F50: JS | G50: JM | H50: JL | I50: JXL | R50: CTN | S50: PCS | T50: CARTON | U50: CARTON | V50: ( Kg ) | W50: ( Kg ) | X50: MEAS | Z50: WEIGHT
A51: TJ12050-010 | B51: FC UTRECHT PERFORMANCE MIDLAYER TOP | C51: 25-02159C-1 | D51: 004 | E51: 18 | O51: =Q41+1 -> 6 | Q51: =O51+R51-1 -> 6 | R51: 1 | S51: =SUM(E51:N51)*R51 -> 18 | T51: 3.5 | U51: 2.52 | V51: 3.5 | W51: 2.52 | X51: 597X292X191 | Y51: =IF(X51="595X289X390",0.071,IF(X51="597X292X191",0.034,IF(X51="560X600X390",0.132,IF(X51="560X400X390",0.088))))*R51 -> 0.034 | Z51: 0
F52: 20 | O52: =Q51+1 -> 7 | Q52: =O52+R52-1 -> 7 | R52: 1 | S52: =SUM(E52:N52)*R52 -> 20 | T52: 5.74 | U52: 4.16 | V52: 5.74 | W52: 4.16 | X52: 597X292X191 | Y52: =IF(X52="595X289X390",0.071,IF(X52="597X292X191",0.034,IF(X52="560X600X390",0.132,IF(X52="560X400X390",0.088))))*R52 -> 0.034 | Z52: 0
G53: 20 | O53: =Q52+1 -> 8 | Q53: =O53+R53-1 -> 8 | R53: 1 | S53: =SUM(E53:N53)*R53 -> 20 | T53: 6.62 | U53: 5.04 | V53: 6.62 | W53: 5.04 | X53: 597X292X191 | Y53: =IF(X53="595X289X390",0.071,IF(X53="597X292X191",0.034,IF(X53="560X600X390",0.132,IF(X53="560X400X390",0.088))))*R53 -> 0.034 | Z53: 0
...

Sheet CLP
A1: CARGO LOADING PLAN
A3: PACKING LIST NO. | C3: : | D3: 0654/INV/2025
A4: HAWB / HBL NO. | C4: :
A5: PORT OF LOADING | C5: : | D5: SOEKARNO HATTA, JAKARTA AIRPORT, INDONESIA
A6: PORT OF DELIVERY | C6: : | D6: AMSTERDAM, NL
A7: VESSEL / CARRIER NO. | C7: :
A8: ON BOARD DATE | C8: :
A9: SHIP MODE | C9: : | D9: AIR
A10: TRUCK / VEHICLE NO. | C10: :
A11: BOOKING REF. | C11: : | D11: CA25000660
A12: STUFFING DATE | C12: :
A15: FACTORY | B15: PO NO. | D15: ORDER LINE | E15: STYLE / COL. NO. | F15: OP NO. | G15: STYLE NAME | H15: HTS CODE | I15: QTY. CTNS. | J15: QTY. PCS | K15: GW | L15: NW | M15: CBM
A16: MIF 2 | B16: EPO12508755 | D16: 1 | E16: TI12081-010 | F16: 25-02175B-1 | G16: FC UTRECHT PERFORMANCE KNIT SUIT | H16: 61109000 | I16: ='PL FC Utrecht'!R33 -> 4 | J16: ='PL FC Utrecht'!S33 -> 100 | K16: ='PL FC Utrecht'!V33 -> 45.44 | L16: ='PL FC Utrecht'!W33 -> 39.6 | M16: ='PL FC Utrecht'!Y33 -> 0.284
A17: MIF 2 | B17: EPO12508755 | D17: 3 | E17: TJ12049-010 | F17: 25-02168C-1 | G17: FC UTRECHT PERFORMANCE KNIT SHORT- PKTS | H17: 61034900 | I17: ='PL FC Utrecht'!R43 -> 1 | J17: ='PL FC Utrecht'!S43 -> 100 | K17: ='PL FC Utrecht'!V43 -> 35.66 | L17: ='PL FC Utrecht'!W43 -> 30.76 | M17: ='PL FC Utrecht'!Y43 -> 0.071
A18: MIF 2 | B18: EPO12508755 | D18: 4 | E18: TJ12050-010 | F18: 25-02159C-1 | G18: FC UTRECHT PERFORMANCE MIDLAYER TOP | H18: 61109000 | I18: ='PL FC Utrecht'!R57 -> 6 | J18: ='PL FC Utrecht'!S57 -> 150 | K18: ='PL FC Utrecht'!V57 -> 35.54 | L18: ='PL FC Utrecht'!W57 -> 28.24 | M18: ='PL FC Utrecht'!Y57 -> 0.278
A19: MIF 2 | B19: EPO12508755 | D19: 5 | E19: TJ12052-010 | F19: 25-02174C-1 | G19: FC UTRECHT PERFORMANCE KNIT PANT- PKTS | H19: 61034900 | I19: ='PL FC Utrecht'!R70 -> 4 | J19: ='PL FC Utrecht'!S70 -> 100 | K19: ='PL FC Utrecht'!V70 -> 35.62 | L19: ='PL FC Utrecht'!W70 -> 30.72 | M19: ='PL FC Utrecht'!Y70 -> 0.173
A20: MIF 2 | B20: EPO12508755 | D20: 7 | E20: TM12049-010 | F20: 25-02166C-1 | G20: FC UTRECHT PERFORMANCE KNIT SHORT- PKTS | H20: 61034900 | I20: ='PL FC Utrecht'!R84 -> 5 | J20: ='PL FC Utrecht'!S84 -> 206 | K20: ='PL FC Utrecht'!V84 -> 91.76 | L20: ='PL FC Utrecht'!W84 -> 81.14 | M20: ='PL FC Utrecht'!Y84 -> 0.281
A21: MIF 2 | B21: EPO12508755 | D21: 8 | E21: TM12050-010 | F21: 25-02154C-1 | G21: FC UTRECHT PERFORMANCE MIDLAYER TOP | H21: 61109000 | I21: ='PL FC Utrecht'!R103 -> 13 | J21: ='PL FC Utrecht'!S103 -> 300 | K21: ='PL FC Utrecht'!V103 -> 159.64 | L21: ='PL FC Utrecht'!W103 -> 144.28 | M21: ='PL FC Utrecht'!Y103 -> 0.738
A22: MIF 2 | B22: EPO12508755 | D22: 9 | E22: TM12052-010 | F22: 25-02172C-1 | G22: FC UTRECHT PERFORMANCE KNIT PANT- PKTS | H22: 61034900 | I22: ='PL FC Utrecht'!R120 -> 8 | J22: ='PL FC Utrecht'!S120 -> 202 | K22: ='PL FC Utrecht'!V120 -> 90.1 | L22: ='PL FC Utrecht'!W120 -> 81.06 | M22: ='PL FC Utrecht'!Y120 -> 0.457
A23: MIF 2 | B23: EPO12508755 | D23: 2 | E23: TJ12046-072 | F23: 25-02151B-1 | G23: FC UTRECHT PERFORMANCE SHORT SLEEVE TEE | H23: 61099020 | I23: ='PL FC Utrecht'!R131 -> 3 | J23: ='PL FC Utrecht'!S131 -> 200 | K23: ='PL FC Utrecht'!V131 -> 10.76 | L23: ='PL FC Utrecht'!W131 -> 7.82 | M23: ='PL FC Utrecht'!Y131 -> 0.139
A24: MIF 2 | B24: EPO12508755 | D24: 6 | E24: TM12046-072 | F24: 25-02146C-1 | G24: FC UTRECHT PERFORMANCE SHORT SLEEVE TEE | H24: 61099020 | I24: ='PL FC Utrecht'!R147 -> 8 | J24: ='PL FC Utrecht'!S147 -> 400 | K24: ='PL FC Utrecht'!V147 -> 71.3 | L24: ='PL FC Utrecht'!W147 -> 61.06 | M24: ='PL FC Utrecht'!Y147 -> 0.42
A25: MIF 2 | B25: WPO12508771 | D25: 1 | E25: TI12081-010 | F25: 25-02175B-2 | G25: FC UTRECHT PERFORMANCE KNIT SUIT | H25: 61109000 | I25: ='PL FC Utrecht'!R217 -> 1 | J25: ='PL FC Utrecht'!S217 -> 25 | K25: ='PL FC Utrecht'!V217 -> 11.69 | L25: ='PL FC Utrecht'!W217 -> 9.85 | M25: ='PL FC Utrecht'!Y217 -> 0.088
A26: MIF 2 | B26: WPO12508771 | D26: 2 | E26: TJ12046-072 | F26: 25-02151B-3 | G26: FC UTRECHT PERFORMANCE SHORT SLEEVE TEE | H26: 61099020 | I26: ='PL FC Utrecht'!R228 -> 3 | J26: ='PL FC Utrecht'!S228 -> 171 | K26: ='PL FC Utrecht'!V228 -> 26.31 | L26: ='PL FC Utrecht'!W228 -> 20.21 | M26: ='PL FC Utrecht'!Y228 -> 0.139
A27: MIF 2 | B27: WPO12508771 | D27: 3 | E27: TJ12049-010 | F27: 25-02168C-2 | G27: FC UTRECHT PERFORMANCE KNIT SHORT- PKTS | H27: 61034900 | I27: ='PL FC Utrecht'!R238 -> 2 | J27: ='PL FC Utrecht'!S238 -> 141 | K27: ='PL FC Utrecht'!V238 -> 50.3 | L27: ='PL FC Utrecht'!W238 -> 44.8 | M27: ='PL FC Utrecht'!Y238 -> 0.105
A28: MIF 2 | B28: WPO12508771 | D28: 4 | E28: TJ12050-010 | F28: 25-02159C-3 | G28: FC UTRECHT PERFORMANCE MIDLAYER TOP | H28: 61109000 | I28: ='PL FC Utrecht'!R250 -> 4 | J28: ='PL FC Utrecht'!S250 -> 126 | K28: ='PL FC Utrecht'!V250 -> 31.28 | L28: ='PL FC Utrecht'!W250 -> 24.58 | M28: ='PL FC Utrecht'!Y250 -> 0.247
A29: MIF 2 | B29: WPO12508771 | D29: 5 | E29: TJ12052-010 | F29: 25-02174C-3 | G29: FC UTRECHT PERFORMANCE KNIT PANT- PKTS | H29: 61034900 | I29: ='PL FC Utrecht'!R262 -> 4 | J29: ='PL FC Utrecht'!S262 -> 119 | K29: ='PL FC Utrecht'!V262 -> 42.34 | L29: ='PL FC Utrecht'!W262 -> 37.44 | M29: ='PL FC Utrecht'!Y262 -> 0.21
A30: MIF 2 | B30: WPO12508771 | D30: 7 | E30: TM12049-010 | F30: 25-02166C-3 | G30: FC UTRECHT PERFORMANCE KNIT SHORT- PKTS | H30: 61034900 | I30: ='PL FC Utrecht'!R275 -> 5 | J30: ='PL FC Utrecht'!S275 -> 162 | K30: ='PL FC Utrecht'!V275 -> 68.76 | L30: ='PL FC Utrecht'!W275 -> 60.7 | M30: ='PL FC Utrecht'!Y275 -> 0.207
A31: MIF 2 | B31: WPO12508771 | D31: 8 | E31: TM12050-010 | F31: 25-02154C-5 | G31: FC UTRECHT PERFORMANCE MIDLAYER TOP | H31: 61109000 | I31: ='PL FC Utrecht'!R288 -> 5 | J31: ='PL FC Utrecht'!S288 -> 134 | K31: ='PL FC Utrecht'!V288 -> 68.57 | L31: ='PL FC Utrecht'!W288 -> 58.93 | M31: ='PL FC Utrecht'!Y288 -> 0.318
A32: MIF 2 | B32: WPO12508771 | D32: 9 | E32: TM12052-010 | F32: 25-02172C-4 | G32: FC UTRECHT PERFORMANCE KNIT PANT- PKTS | H32: 61034900 | I32: ='PL FC Utrecht'!R302 -> 6 | J32: ='PL FC Utrecht'!S302 -> 124 | K32: ='PL FC Utrecht'!V302 -> 55 | L32: ='PL FC Utrecht'!W302 -> 46.94 | M32: ='PL FC Utrecht'!Y302 -> 0.315
A33: MIF 2 | B33: WPO12508771 | D33: 6 | E33: TM12046-072 | F33: 25-02146C-5 | G33: FC UTRECHT PERFORMANCE SHORT SLEEVE TEE | H33: 61099020 | I33: ='PL FC Utrecht'!R315 -> 5 | J33: ='PL FC Utrecht'!S315 -> 198 | K33: ='PL FC Utrecht'!V315 -> 26.31 | L33: ='PL FC Utrecht'!W315 -> 20.21 | M33: ='PL FC Utrecht'!Y315 -> 0.207
A34: MIF 2 | B34: WPO12508772 | D34: 1 | E34: TI12081-090 | F34: 25-02175B-3 | G34: FC UTRECHT PERFORMANCE KNIT SUIT | H34: 61109000 | I34: ='PL FC Utrecht'!R336 -> 1 | J34: ='PL FC Utrecht'!S336 -> 25 | K34: ='PL FC Utrecht'!V336 -> 11.69 | L34: ='PL FC Utrecht'!W336 -> 9.85 | M34: ='PL FC Utrecht'!Y336 -> 0.088
A35: MIF 2 | B35: WPO12508772 | D35: 2 | E35: TJ12046-090 | F35: 25-02151B-4 | G35: FC UTRECHT PERFORMANCE SHORT SLEEVE TEE | H35: 61099020 | I35: ='PL FC Utrecht'!R346 -> 1 | J35: ='PL FC Utrecht'!S346 -> 25 | K35: ='PL FC Utrecht'!V346 -> 5.91 | L35: ='PL FC Utrecht'!W346 -> 4.95 | M35: ='PL FC Utrecht'!Y346 -> 0.034
A36: MIF 2 | B36: WPO12508772 | D36: 6 | E36: TM12046-090 | F36: 25-02146C-6 | G36: FC UTRECHT PERFORMANCE SHORT SLEEVE TEE | H36: 61099020 | I36: ='PL FC Utrecht'!R356 -> 1 | J36: ='PL FC Utrecht'!S356 -> 26 | K36: ='PL FC Utrecht'!V356 -> 6.098 | L36: ='PL FC Utrecht'!W356 -> 5.138 | M36: ='PL FC Utrecht'!Y356 -> 0.034
A37: MIF 2 | B37: WPO12508772 | D37: 4 | E37: TJ12050-090 | F37: 25-02159C-4 | G37: FC UTRECHT PERFORMANCE MIDLAYER TOP | H37: 61109000 | I37: ='PL FC Utrecht'!R366 -> 1 | J37: ='PL FC Utrecht'!S366 -> 25 | K37: ='PL FC Utrecht'!V366 -> 1.12 | L37: ='PL FC Utrecht'!W366 -> 0.14 | M37: ='PL FC Utrecht'!Y366 -> 0.034
A38: MIF 2 | B38: WPO12508772 | D38: 5 | E38: TJ12052-090 | F38: 25-02174C-4 | G38: FC UTRECHT PERFORMANCE KNIT PANT- PKTS | H38: 61099020 | I38: ='PL FC Utrecht'!R376 -> 1 | J38: ='PL FC Utrecht'!S376 -> 25 | K38: ='PL FC Utrecht'!V376 -> 2.28 | L38: ='PL FC Utrecht'!W376 -> 1.3 | M38: ='PL FC Utrecht'!Y376 -> 0.034
A39: MIF 2 | B39: WPO12508772 | D39: 8 | E39: TM12050-090 | F39: 25-02154C-6 | G39: FC UTRECHT PERFORMANCE MIDLAYER TOP | H39: 61034900 | I39: ='PL FC Utrecht'!R386 -> 1 | J39: ='PL FC Utrecht'!S386 -> 26 | K39: ='PL FC Utrecht'!V386 -> 2.27 | L39: ='PL FC Utrecht'!W386 -> 1.29 | M39: ='PL FC Utrecht'!Y386 -> 0.034
A40: MIF 2 | B40: WPO12508772 | D40: 9 | E40: TM12052-090 | F40: 25-02172C-5 | G40: FC UTRECHT PERFORMANCE KNIT PANT- PKTS | H40: 61099020 | I40: ='PL FC Utrecht'!R396 -> 1 | J40: ='PL FC Utrecht'!S396 -> 26 | K40: ='PL FC Utrecht'!V396 -> 2.06 | L40: ='PL FC Utrecht'!W396 -> 1.08 | M40: ='PL FC Utrecht'!Y396 -> 0.034
A41: MIF 2 | B41: WPO12508772 | D41: 3 | E41: TJ12049-090 | F41: 25-02168C-3 | G41: FC UTRECHT PERFORMANCE KNIT SHORT- PKTS | H41: 61034900 | I41: ='PL FC Utrecht'!R406 -> 1 | J41: ='PL FC Utrecht'!S406 -> 25 | K41: ='PL FC Utrecht'!V406 -> 2.28 | L41: ='PL FC Utrecht'!W406 -> 1.3 | M41: ='PL FC Utrecht'!Y406 -> 0.034
A42: MIF 2 | B42: WPO12508772 | D42: 7 | E42: TM12049-090 | F42: 25-02166C-4 | G42: FC UTRECHT PERFORMANCE KNIT SHORT- PKTS | H42: 61034900 | I42: ='PL FC Utrecht'!R416 -> 1 | J42: ='PL FC Utrecht'!S416 -> 26 | K42: ='PL FC Utrecht'!V416 -> 2.06 | L42: ='PL FC Utrecht'!W416 -> 1.08 | M42: ='PL FC Utrecht'!Y416 -> 0.034
A43: MIF 2 | B43: EPO12508757 | D43: 3 | E43: TJ12050-090 | F43: 25-02159C-2 | G43: FC UTRECHT PERFORMANCE MIDLAYER TOP | H43: 61109000 | I43: ='PL FC Utrecht'!R170 -> 6 | J43: ='PL FC Utrecht'!S170 -> 152 | K43: ='PL FC Utrecht'!V170 -> 35.98 | L43: ='PL FC Utrecht'!W170 -> 28.68 | M43: ='PL FC Utrecht'!Y170 -> 0.241
...
